<mujoco model="go2_description">
  <compiler angle="radian" meshdir="../mujoco_meshes/" autolimits="true"/>
  
  <option timestep="0.005" gravity="0 0 -9.81"/>

  <asset>
    <mesh name="base" file="base.stl"/>
    <mesh name="hip" file="hip.stl"/>
    <mesh name="thigh" file="thigh.stl"/>
    <mesh name="calf" file="calf.stl"/>
    <mesh name="foot" file="foot.stl"/>
    <mesh name="thigh_mirror" file="thigh_mirror.stl"/>
    <mesh name="calf_mirror" file="calf_mirror.stl"/>
    <texture name="grid" type="2d" builtin="checker" rgb1=".1 .2 .3" rgb2=".2 .3 .4" width="300" height="300" mark="edge" markrgb=".8 .8 .8"/>
    <material name="grid_mat" texture="grid" texrepeat="2 2" texuniform="true"/>
  </asset>

  <worldbody>
    <body name="base" pos="0 0 0.445"> 
      <inertial pos="0.021112 0 -0.005366" quat="-0.000543471 0.713435 -0.00173769 0.700719"
        mass="6.921"
        diaginertia="0.107027 0.0980771 0.0244531" />
      <geom type="mesh" contype="0" conaffinity="0" group="0" density="0" rgba="1 1 1 1" mesh="base"/>
      <geom size="0.1881 0.04675 0.057" type="box" rgba="1 1 1 1"/>
      <geom size="0.05 0.045" pos="0.285 0 0.01" type="cylinder"/>
      <geom size="0.047" pos="0.293 0 -0.06"/>
      <freejoint/>
      <site name="imu_site" pos="-0.02557 0 0.04232"/>
      <camera name="front_depth_camera" pos="0.28 0 0" fovy="60" ipd="0.06"/> 
      <body name="FL_hip" pos="0.1934 0.0465 0">
        <inertial pos="-0.0054 0.00194 -0.000105" quat="0.497014 0.499245 0.505462 0.498237" mass="0.678" diaginertia="0.00088403 0.000596003 0.000479967"/>
        <joint name="FL_hip_joint" pos="0 0 0" axis="1 0 0" range="-1.0472 1.0472" actuatorfrcrange="-23.7 23.7"/>
        <geom type="mesh" contype="0" conaffinity="0" group="0" density="0" rgba="1 1 1 1" mesh="hip"/>
        <geom size="0.046 0.02" pos="0 0.08 0" quat="0.707107 0.707107 0 0" type="cylinder" rgba="1 1 1 1"/>
        <body name="FL_thigh" pos="0 0.0955 0">
          <inertial pos="-0.00374 -0.0223 -0.0327" quat="0.829533 0.0847635 -0.0200632 0.551623" mass="1.152" diaginertia="0.00594973 0.00584149 0.000878787"/>
          <joint name="FL_thigh_joint" pos="0 0 0" axis="0 1 0" range="-1.5708 3.4907" actuatorfrcrange="-23.7 23.7"/>
          <geom type="mesh" contype="0" conaffinity="0" group="0" density="0" rgba="1 1 1 1" mesh="thigh"/>
          <geom size="0.1065 0.01225 0.017" pos="0 0 -0.1065" quat="0.707107 0 0.707107 0" type="box" rgba="1 1 1 1"/>
          <body name="FL_calf" pos="0 0 -0.213">
            <site name="FL_foot_site" pos="0 0 -0.213" size="0.01"/>
            <inertial pos="0.00629595 -0.000622121 -0.141417" quat="0.710749 0.00140574 -0.00463741 0.703429" mass="0.241352" diaginertia="0.0014901 0.00146367 5.30286e-05"/>
            <joint name="FL_calf_joint" pos="0 0 0" axis="0 1 0" range="-2.7227 -0.83776" actuatorfrcrange="-45.43 45.43"/>
            <geom type="mesh" contype="0" conaffinity="0" group="0" density="0" rgba="1 1 1 1" mesh="calf"/>
            <geom size="0.012 0.06" pos="0.008 0 -0.06" quat="0.994493 0 -0.104807 0" type="cylinder" rgba="1 1 1 1"/>
            <geom size="0.011 0.0325" pos="0.02 0 -0.148" quat="0.999688 0 0.0249974 0" type="cylinder"/>
            <geom size="0.0155 0.015" pos="0.00801333 0 -0.18745" quat="0.965093 0 0.261909 0" type="cylinder"/>
            <geom pos="0 0 -0.213" quat="1 0 0 0" type="mesh" contype="0" conaffinity="0" group="0" density="0" rgba="1 1 1 1" mesh="foot"/>
            <geom size="0.022" pos="-0.002 0 -0.213" rgba="1 1 1 1" friction="0.8" condim="3"/>
          </body>
        </body>
      </body>
      <body name="FR_hip" pos="0.1934 -0.0465 0">
        <inertial pos="-0.0054 -0.00194 -0.000105" quat="0.498237 0.505462 0.499245 0.497014" mass="0.678" diaginertia="0.00088403 0.000596003 0.000479967"/>
        <joint name="FR_hip_joint" pos="0 0 0" axis="1 0 0" range="-1.0472 1.0472" actuatorfrcrange="-23.7 23.7"/>
        <geom quat="4.63268e-05 1 0 0" type="mesh" contype="0" conaffinity="0" group="0" density="0" rgba="1 1 1 1" mesh="hip"/>
        <geom size="0.046 0.02" pos="0 -0.08 0" quat="0.707107 0.707107 0 0" type="cylinder" rgba="1 1 1 1"/>
        <body name="FR_thigh" pos="0 -0.0955 0">
          <inertial pos="-0.00374 0.0223 -0.0327" quat="0.551623 -0.0200632 0.0847635 0.829533" mass="1.152" diaginertia="0.00594973 0.00584149 0.000878787"/>
          <joint name="FR_thigh_joint" pos="0 0 0" axis="0 1 0" range="-1.5708 3.4907" actuatorfrcrange="-23.7 23.7"/>
          <geom type="mesh" contype="0" conaffinity="0" group="0" density="0" rgba="1 1 1 1" mesh="thigh_mirror"/>
          <geom size="0.1065 0.01225 0.017" pos="0 0 -0.1065" quat="0.707107 0 0.707107 0" type="box" rgba="1 1 1 1"/>
          <body name="FR_calf" pos="0 0 -0.213">
            <site name="FR_foot_site" pos="0 0 -0.213" size="0.01"/>
            <inertial pos="0.00629595 0.000622121 -0.141417" quat="0.703429 -0.00463741 0.00140574 0.710749" mass="0.241352" diaginertia="0.0014901 0.00146367 5.30286e-05"/>
            <joint name="FR_calf_joint" pos="0 0 0" axis="0 1 0" range="-2.7227 -0.83776" actuatorfrcrange="-45.43 45.43"/>
            <geom type="mesh" contype="0" conaffinity="0" group="0" density="0" rgba="1 1 1 1" mesh="calf_mirror"/>
            <geom size="0.013 0.06" pos="0.01 0 -0.06" quat="0.995004 0 -0.0998334 0" type="cylinder" rgba="1 1 1 1"/>
            <geom size="0.011 0.0325" pos="0.02 0 -0.148" quat="0.999688 0 0.0249974 0" type="cylinder"/>
            <geom size="0.0155 0.015" pos="0.00801333 0 -0.18745" quat="0.965093 0 0.261909 0" type="cylinder"/>
            <geom pos="0 0 -0.213" quat="1 0 0 0" type="mesh" contype="0" conaffinity="0" group="0" density="0" rgba="1 1 1 1" mesh="foot"/>
            <geom size="0.022" pos="-0.002 0 -0.213" rgba="1 1 1 1" friction="0.8" condim="3"/>
          </body>
        </body>
      </body>
      <body name="RL_hip" pos="-0.1934 0.0465 0">
        <inertial pos="0.0054 0.00194 -0.000105" quat="0.505462 0.498237 0.497014 0.499245" mass="0.678" diaginertia="0.00088403 0.000596003 0.000479967"/>
        <joint name="RL_hip_joint" pos="0 0 0" axis="1 0 0" range="-1.0472 1.0472" actuatorfrcrange="-23.7 23.7"/>
        <geom quat="4.63268e-05 0 1 0" type="mesh" contype="0" conaffinity="0" group="0" density="0" rgba="1 1 1 1" mesh="hip"/>
        <geom size="0.046 0.02" pos="0 0.08 0" quat="0.707107 0.707107 0 0" type="cylinder" rgba="1 1 1 1"/>
        <body name="RL_thigh" pos="0 0.0955 0">
          <inertial pos="-0.00374 -0.0223 -0.0327" quat="0.829533 0.0847635 -0.0200632 0.551623" mass="1.152" diaginertia="0.00594973 0.00584149 0.000878787"/>
          <joint name="RL_thigh_joint" pos="0 0 0" axis="0 1 0" range="-0.5236 4.5379" actuatorfrcrange="-23.7 23.7"/>
          <geom type="mesh" contype="0" conaffinity="0" group="0" density="0" rgba="1 1 1 1" mesh="thigh"/>
          <geom size="0.1065 0.01225 0.017" pos="0 0 -0.1065" quat="0.707107 0 0.707107 0" type="box" rgba="1 1 1 1"/>
          <body name="RL_calf" pos="0 0 -0.213">
            <site name="RL_foot_site" pos="0 0 -0.213" size="0.01"/>
            <inertial pos="0.00629595 -0.000622121 -0.141417" quat="0.710749 0.00140574 -0.00463741 0.703429" mass="0.241352" diaginertia="0.0014901 0.00146367 5.30286e-05"/>
            <joint name="RL_calf_joint" pos="0 0 0" axis="0 1 0" range="-2.7227 -0.83776" actuatorfrcrange="-45.43 45.43"/>
            <geom type="mesh" contype="0" conaffinity="0" group="0" density="0" rgba="1 1 1 1" mesh="calf"/>
            <geom size="0.013 0.06" pos="0.01 0 -0.06" quat="0.995004 0 -0.0998334 0" type="cylinder" rgba="1 1 1 1"/>
            <geom size="0.011 0.0325" pos="0.02 0 -0.148" quat="0.999688 0 0.0249974 0" type="cylinder"/>
            <geom size="0.0155 0.015" pos="0.00801333 0 -0.18745" quat="0.965093 0 0.261909 0" type="cylinder"/>
            <geom pos="0 0 -0.213" quat="1 0 0 0" type="mesh" contype="0" conaffinity="0" group="0" density="0" rgba="1 1 1 1" mesh="foot"/>
            <geom size="0.022" pos="-0.002 0 -0.213" rgba="1 1 1 1" friction="0.8" condim="3"/>
          </body>
        </body>
      </body>
      <body name="RR_hip" pos="-0.1934 -0.0465 0">
        <inertial pos="0.0054 -0.00194 -0.000105" quat="0.499245 0.497014 0.498237 0.505462" mass="0.678" diaginertia="0.00088403 0.000596003 0.000479967"/>
        <joint name="RR_hip_joint" pos="0 0 0" axis="1 0 0" range="-1.0472 1.0472" actuatorfrcrange="-23.7 23.7"/>
        <geom quat="2.14617e-09 4.63268e-05 4.63268e-05 -1" type="mesh" contype="0" conaffinity="0" group="0" density="0" rgba="1 1 1 1" mesh="hip"/>
        <geom size="0.046 0.02" pos="0 -0.08 0" quat="0.707107 0.707107 0 0" type="cylinder" rgba="1 1 1 1"/>
        <body name="RR_thigh" pos="0 -0.0955 0">
          <inertial pos="-0.00374 0.0223 -0.0327" quat="0.551623 -0.0200632 0.0847635 0.829533" mass="1.152" diaginertia="0.00594973 0.00584149 0.000878787"/>
          <joint name="RR_thigh_joint" pos="0 0 0" axis="0 1 0" range="-0.5236 4.5379" actuatorfrcrange="-23.7 23.7"/>
          <geom type="mesh" contype="0" conaffinity="0" group="0" density="0" rgba="1 1 1 1" mesh="thigh_mirror"/>
          <geom size="0.1065 0.01225 0.017" pos="0 0 -0.1065" quat="0.707107 0 0.707107 0" type="box" rgba="1 1 1 1"/>
          <body name="RR_calf" pos="0 0 -0.213">
            <site name="RR_foot_site" pos="0 0 -0.213" size="0.01"/>
            <inertial pos="0.00629595 0.000622121 -0.141417" quat="0.703429 -0.00463741 0.00140574 0.710749" mass="0.241352" diaginertia="0.0014901 0.00146367 5.30286e-05"/>
            <joint name="RR_calf_joint" pos="0 0 0" axis="0 1 0" range="-2.7227 -0.83776" actuatorfrcrange="-45.43 45.43"/>
            <geom type="mesh" contype="0" conaffinity="0" group="0" density="0" rgba="1 1 1 1" mesh="calf_mirror"/>
            <geom size="0.013 0.06" pos="0.01 0 -0.06" quat="0.995004 0 -0.0998334 0" type="cylinder" rgba="1 1 1 1"/>
            <geom size="0.011 0.0325" pos="0.02 0 -0.148" quat="0.999688 0 0.0249974 0" type="cylinder"/>
            <geom size="0.0155 0.015" pos="0.00801333 0 -0.18745" quat="0.965093 0 0.261909 0" type="cylinder"/>
            <geom pos="0 0 -0.213" quat="1 0 0 0" type="mesh" contype="0" conaffinity="0" group="0" density="0" rgba="1 1 1 1" mesh="foot"/>
            <geom size="0.022" pos="-0.002 0 -0.213" rgba="1 1 1 1" friction="0.8" condim="3"/>
          </body>
        </body>
      </body>
    </body>
    <geom name="floor" type="plane" size="0 0 .05" material="grid_mat" friction="1.0 0.005 0.0001"/>
  </worldbody>

  <sensor>
    <gyro name="gyro" site="imu_site"/>
    
    <accelerometer name="accelerometer" site="imu_site"/>
    
    <touch name="FL_touch" site="FL_foot_site"/>
    <touch name="FR_touch" site="FR_foot_site"/>
    <touch name="RL_touch" site="RL_foot_site"/>
    <touch name="RR_touch" site="RR_foot_site"/>
  </sensor>

<actuator>
  <motor name="FL_hip_joint"   joint="FL_hip_joint"   forcerange="-23.7 23.7" ctrlrange="-23.7 23.7" ctrllimited="true"/>
  <motor name="FL_thigh_joint" joint="FL_thigh_joint" forcerange="-23.7 23.7" ctrlrange="-23.7 23.7" ctrllimited="true"/>
  <motor name="FL_calf_joint"  joint="FL_calf_joint"  forcerange="-45.4 45.4" ctrlrange="-23.7 23.7" ctrllimited="true"/>

  <motor name="FR_hip_joint"   joint="FR_hip_joint"   forcerange="-23.7 23.7" ctrlrange="-23.7 23.7" ctrllimited="true"/>
  <motor name="FR_thigh_joint" joint="FR_thigh_joint" forcerange="-23.7 23.7" ctrlrange="-23.7 23.7" ctrllimited="true"/>
  <motor name="FR_calf_joint"  joint="FR_calf_joint"  forcerange="-45.4 45.4" ctrlrange="-23.7 23.7" ctrllimited="true"/>

  <motor name="RL_hip_joint"   joint="RL_hip_joint"   forcerange="-23.7 23.7" ctrlrange="-23.7 23.7" ctrllimited="true"/>
  <motor name="RL_thigh_joint" joint="RL_thigh_joint" forcerange="-23.7 23.7" ctrlrange="-23.7 23.7" ctrllimited="true"/>
  <motor name="RL_calf_joint"  joint="RL_calf_joint"  forcerange="-45.4 45.4" ctrlrange="-23.7 23.7" ctrllimited="true"/>

  <motor name="RR_hip_joint"   joint="RR_hip_joint"   forcerange="-23.7 23.7" ctrlrange="-23.7 23.7" ctrllimited="true"/>
  <motor name="RR_thigh_joint" joint="RR_thigh_joint" forcerange="-23.7 23.7" ctrlrange="-23.7 23.7" ctrllimited="true"/>
  <motor name="RR_calf_joint"  joint="RR_calf_joint"  forcerange="-45.4 45.4" ctrlrange="-23.7 23.7" ctrllimited="true"/>
</actuator>
</mujoco>
